<?xml version="1.0"?>
<robot name="wheely_dan" xmlns:xacro="http://www.ros.org/wiki/xacro">

    <xacro:include filename="inertial_macros.xacro" />
    
    <material name="white">
        <color rgba="1 1 1 1"/>
    </material>

    <material name="red">
        <color rgba="1 0 0 1"/>
    </material>

    <material name="orange">
        <color rgba="1 0.3 0.1 1"/>
    </material>

    <material name="blue">
        <color rgba="0.2 0.2 1 1"/>
    </material>

    <material name="black">
        <color rgba="0 0 0 1"/>
    </material>

    <material name="grey">
        <color rgba="0.5 0.5 0.5 1"/>
    </material>

    <material name="green">
        <color rgba="0 1 0 1"/>
    </material>

    <!-- ========= BASE ========= -->

    <link name="base_link">

    </link>

    <!-- ========= CHASSIS ========= -->

    <link name="chassis_link">
        <visual>
        <geometry>
            <mesh filename="file:///home/logicbomb/Projects/SLAM/wheely-dan/src/wd_description/meshes/chassis_link.stl" scale="0.001 0.001 0.001"/>
        </geometry>
        <material name="black"/>
        </visual>

        <collision>
        <geometry>
            <mesh filename="file:///home/logicbomb/Projects/SLAM/wheely-dan/src/wd_description/meshes/chassis_link.stl" scale="0.001 0.001 0.001"/>
        </geometry>
        </collision>

        <xacro:inertial_box mass="m" x="x" y="y" z="z">
            <origin xyz="" rpy="0 0 0"/>
        </xacro:inertial_box>  
    </link>

    <joint name="chassis_joint" type="fixed">
        <parent link="base_link"/>
        <child link="chassis_link"/>
        <origin xyz="-0.035 0 0"/>
    </joint>  


    <!-- ========= JETSON ========= -->

    <link name="jetson_link">
        <visual>
        <geometry>
            <mesh filename="file:///home/logicbomb/Projects/SLAM/wheely-dan/src/wd_description/meshes/jetson_link.stl" scale="0.001 0.001 0.001"/>
        </geometry>
        <material name="grey"/>
        </visual>

        <collision>
        <geometry>
            <mesh filename="file:///home/logicbomb/Projects/SLAM/wheely-dan/src/wd_description/meshes/jetson_link.stl" scale="0.001 0.001 0.001"/>
        </geometry>
        </collision>

        <xacro:inertial_box mass="m" x="x" y="y" z="z">
            <origin xyz="" rpy="0 0 0"/>
        </xacro:inertial_box>        
    </link>

    <joint name="jetson_joint" type="fixed">
        <parent link="base_link"/>
        <child link="jetson_link"/>
        <origin xyz="0.12625 0 0.057"/>
    </joint>

    
    <!-- ========= BATTERY ========= -->

    <link name="battery_link">
        <visual>
        <geometry>
            <mesh filename="file:///home/logicbomb/Projects/SLAM/wheely-dan/src/wd_description/meshes/battery_link.stl" scale="0.001 0.001 0.001"/>
        </geometry>
        </material name="red"/>
        </visual>

        <collision>
        <geometry>
            <mesh filename="file:///home/logicbomb/Projects/SLAM/wheely-dan/src/wd_description/meshes/battery_link.stl" scale="0.001 0.001 0.001"/>
        </geometry>
        </collision>

        <xacro:inertial_box mass="m" x="x" y="y" z="z">
            <origin xyz="" rpy="0 0 0"/>
        </xacro:inertial_box>  
    </link>

    <joint name="battery_joint" type="fixed">
        <parent link="base_link"/>
        <child link="battery_link"/>
        <origin xyz="0.163 0 0.011"/>
    </joint>

    <!-- ========= PCB ========= -->

    <link name="pcb_link">
        <visual>
        <geometry>
            <mesh filename="file:///home/logicbomb/Projects/SLAM/wheely-dan/src/wd_description/meshes/pcb_link.stl" scale="0.001 0.001 0.001"/>
        </geometry>
        <material name="green"/>
        </visual>

        <collision>
        <geometry>
            <mesh filename="file:///home/logicbomb/Projects/SLAM/wheely-dan/src/wd_description/meshes/pcb_link.stl" scale="0.001 0.001 0.001"/>
        </geometry>
        </collision>

        <xacro:inertial_box mass="m" x="x" y="y" z="z">
            <origin xyz="" rpy="0 0 0"/>
        </xacro:inertial_box>  
    </link>

    <joint name="pcb_joint" type="fixed">
        <parent link="base_link"/>
        <child link="pcb_link"/>
        <origin xyz="0.005 0 0.065"/>
    </joint>


    <!-- ========= MOTOR DRIVER L ========= -->

    <link name="driver_left_link">
        <visual>
        <geometry>
            <mesh filename="file:///home/logicbomb/Projects/SLAM/wheely-dan/src/wd_description/meshes/driver_left_link.stl" scale="0.001 0.001 0.001"/>
        </geometry>
        <material name="black"/>
        </visual>

        <collision>
        <geometry>
            <mesh filename="file:///home/logicbomb/Projects/SLAM/wheely-dan/src/wd_description/meshes/driver_left_link.stl" scale="0.001 0.001 0.001"/>
        </geometry>
        </collision>

        <xacro:inertial_box mass="m" x="x" y="y" z="z">
            <origin xyz="" rpy="0 0 0"/>
        </xacro:inertial_box>  
    </link>

    <joint name="driver_left_joint" type="fixed">
        <parent link="base_link"/>
        <child link="driver_left_link"/>
        <origin xyz="0.04576 0.03548 0.018"/>
    </joint>

    <!-- ========= MOTOR DRIVER R ========= -->

    <link name="driver_right_link">
        <visual>
        <geometry>
            <mesh filename="file:///home/logicbomb/Projects/SLAM/wheely-dan/src/wd_description/meshes/driver_right_link.stl" scale="0.001 0.001 0.001"/>
        </geometry>
        <material name="black"/>
        </visual>

        <collision>
        <geometry>
            <mesh filename="file:///home/logicbomb/Projects/SLAM/wheely-dan/src/wd_description/meshes/driver_right_link.stl" scale="0.001 0.001 0.001"/>
        </geometry>
        </collision>

        <xacro:inertial_box mass="m" x="x" y="y" z="z">
            <origin xyz="" rpy="0 0 0"/>
        </xacro:inertial_box>  
    </link>

    <joint name="driver_right_joint" type="fixed">
        <parent link="base_link"/>
        <child link="driver_right_link"/>
        <origin xyz="0.04576 -0.03548 0.018"/>
    </joint>


    <!-- ========= WHEEL L ========= -->

    <link name="wheel_left_link">
        <visual>
        <geometry>
            <mesh filename="file:///home/logicbomb/Projects/SLAM/wheely-dan/src/wd_description/meshes/wheel_left_link.stl" scale="0.001 0.001 0.001"/>
        </geometry>
        <material name="blue"/>
        </visual>

        <collision>
        <geometry>
            <mesh filename="file:///home/logicbomb/Projects/SLAM/wheely-dan/src/wd_description/meshes/wheel_left_link.stl" scale="0.001 0.001 0.001"/>
        </geometry>
        </collision>

        <xacro:inertial_cylinder mass="0.1" length="0.04" radius="0.05">
            <origin xyz="0 0 0" rpy="0 0 0"/>
        </xacro:inertial_cylinder>
    </link>

    <joint name="wheel_left_joint" type="continuous">
        <parent link="base_link"/>
        <child link="wheel_left_link"/>
        <origin xyz="0 0.098 0.0145"/>
        <axis xyz="0 1 0"/>
    </joint>

    <!-- ========= WHEEL R ========= -->

    <link name="wheel_right_link">
        <visual>
        <geometry>
            <mesh filename="file:///home/logicbomb/Projects/SLAM/wheely-dan/src/wd_description/meshes/wheel_right_link.stl" scale="0.001 0.001 0.001"/>
        </geometry>
        <material name="blue"/>
        </visual>

        <collision>
        <geometry>
            <mesh filename="file:///home/logicbomb/Projects/SLAM/wheely-dan/src/wd_description/meshes/wheel_right_link.stl" scale="0.001 0.001 0.001"/>
        </geometry>
        </collision>

        <xacro:inertial_cylinder mass="0.1" length="0.04" radius="0.05">
            <origin xyz="0 0 0" rpy="0 0 0"/>
        </xacro:inertial_cylinder>
    </link>

    <joint name="wheel_right_joint" type="continuous">
        <parent link="base_link"/>
        <child link="wheel_right_link"/>
        <origin xyz="0 -0.098 0.0145"/>
        <axis xyz="0 1 0"/>
    </joint>


    <!-- ========= CASTER L ========= -->

    <link name="caster_fork_left_link">
        <visual>
        <geometry>
            <mesh filename="file:///home/logicbomb/Projects/SLAM/wheely-dan/src/wd_description/meshes/caster_fork_link.stl" scale="0.001 0.001 0.001"/>
        </geometry>
        <material name="grey"/>
        </visual>

        <collision>
        <geometry>
            <mesh filename="file:///home/logicbomb/Projects/SLAM/wheely-dan/src/wd_description/meshes/caster_fork_link.stl" scale="0.001 0.001 0.001"/>
        </geometry>
        </collision>

        <xacro:inertial_cylinder mass="0.1" length="0.04" radius="0.05">
            <origin xyz="0 0 0" rpy="0 0 0"/>
        </xacro:inertial_cylinder>
    </link>

    <joint name="caster_fork_left_joint" type="fixed">
        <parent link="base_link"/>
        <child link="caster_fork_left_link"/>
        <origin xyz="0.15675 0.05375 -0.0033"/>
    </joint>


    <link name="caster_wheel_left_link">
        <visual>
        <geometry>
            <mesh filename="file:///home/logicbomb/Projects/SLAM/wheely-dan/src/wd_description/meshes/caster_wheel_link.stl" scale="0.001 0.001 0.001"/>
        </geometry>
        <material name="black"/>
        </visual>

        <collision>
        <geometry>
            <mesh filename="file:///home/logicbomb/Projects/SLAM/wheely-dan/src/wd_description/meshes/caster_wheel_link.stl" scale="0.001 0.001 0.001"/>
        </geometry>
        </collision>

        <xacro:inertial_cylinder mass="0.1" length="0.04" radius="0.05">
            <origin xyz="0 0 0" rpy="0 0 0"/>
        </xacro:inertial_cylinder>
    </link>

    <joint name="caster_wheel_left_joint" type="continuous">
        <parent link="caster_fork_left_link"/>
        <child link="caster_wheel_left_link"/>
        <origin xyz="-0.01 0 -0.0107"/>
        <axis xyz="0 1 0"/>
    </joint>

    <!-- ========= CASTER R ========= -->

    <link name="caster_fork_right_link">
        <visual>
        <geometry>
            <mesh filename="file:///home/logicbomb/Projects/SLAM/wheely-dan/src/wd_description/meshes/caster_fork_link.stl" scale="0.001 0.001 0.001"/>
        </geometry>
        <material name="grey"/>
        </visual>

        <collision>
        <geometry>
            <mesh filename="file:///home/logicbomb/Projects/SLAM/wheely-dan/src/wd_description/meshes/caster_fork_link.stl" scale="0.001 0.001 0.001"/>
        </geometry>
        </collision>

        <xacro:inertial_cylinder mass="0.1" length="0.04" radius="0.05">
            <origin xyz="0 0 0" rpy="0 0 0"/>
        </xacro:inertial_cylinder>
    </link>

    <joint name="caster_fork_right_joint" type="fixed">
        <parent link="base_link"/>
        <child link="caster_fork_right_link"/>
        <origin xyz="0.15675 -0.05375 -0.0033"/>
    </joint>


    <link name="caster_wheel_right_link">
        <visual>
        <geometry>
            <mesh filename="file:///home/logicbomb/Projects/SLAM/wheely-dan/src/wd_description/meshes/caster_wheel_link.stl" scale="0.001 0.001 0.001"/>
        </geometry>
        <material name="black"/>
        </visual>

        <collision>
        <geometry>
            <mesh filename="file:///home/logicbomb/Projects/SLAM/wheely-dan/src/wd_description/meshes/caster_wheel_link.stl" scale="0.001 0.001 0.001"/>
        </geometry>
        </collision>

        <xacro:inertial_cylinder mass="0.1" length="0.04" radius="0.05">
            <origin xyz="0 0 0" rpy="0 0 0"/>
        </xacro:inertial_cylinder>
    </link>

    <joint name="caster_wheel_right_joint" type="continuous">
        <parent link="caster_fork_right_link"/>
        <child link="caster_wheel_right_link"/>
        <origin xyz="-0.01 0 -0.0107"/>
        <axis xyz="0 1 0"/>
    </joint>


    <!-- ========= LIDAR ========= -->

    <link name="lidar_link">
        <visual>
        <geometry>
            <mesh filename="file:///home/logicbomb/Projects/SLAM/wheely-dan/src/wd_description/meshes/lidar_link.stl" scale="0.001 0.001 0.001"/>
        </geometry>
        <material name="white"/>
        </visual>

        <collision>
        <geometry>
            <mesh filename="file:///home/logicbomb/Projects/SLAM/wheely-dan/src/wd_description/meshes/lidar_link.stl" scale="0.001 0.001 0.001"/>
        </geometry>
        </collision>

        <!-- done -->
        <xacro:inertial_box mass="0.187" x="0.1" y="0.07" z="0.055">
            <origin xyz="0 0 0.0275" rpy="0 0 0"/>
        </xacro:inertial_box>  
    </link>

    <joint name="lidar_joint" type="fixed">
        <parent link="base_link"/>
        <child link="lidar_link"/>
        <origin xyz="0.006175 0 0.095"/>
    </joint>

</robot>